Workbook

Sheet HIS
A1: HOSPITAL DATA SHEET
A2: HOSPITAL ROHINI ID* | C2: 8900080770423 | G2: ROHINI Expiry Date*: | I2: 17-Aug-2027
A3: Name of Hospital: | B3: PB Health Hospital, MG Road (Medom Healthtech Private Limited)
A4: Address: | B4: L-22, DLF Phase 2, Mehrauli-Gurgaon Road, Sector 25, Near American Public School
A5: City: | B5: Gurugram | C5: State: | D5: Haryana | F5: Pincode: | G5: 122002 | H5: Agreed Tariff :
A6: STD Code: | B6: 0124 | D6: Phone: | E6: 4374109 | G6: Fax: | H6: Nil
A7: E Mail ID: | B7: insurance.mgroad@pbhealth.com | F7: Mobile No. | G7: 7428280579
A8: Type of Provider | B8: Privtate | C8: Yes | D8: Corporate | F8: Charitable Trust | H8: Government
A9: Nature of Entity | B9: Company | D9: Yes | E9: Partnership Firm | H9: LLP
B10: Propritorship Concern | E10: Individual Person | H10: Trust
A11: MAIN CONTACT POINTS
A12: Designation | C12: Name | F12: Mobile No. | H12: E Mail ID
A13: Head of the Organisation / CEO | C13: Alok Man Singh, Hospital Director
A14: MoU Signing Authority | C14: Manoj Sharma, Director / Rajeev Bhandari, Director | F14: 9810302530 / 9873079038 | H14: rajeev.bhandari@pbhealth.com
A15: Marketing | C15: -
A16: TPA Desk | C16: Deepak Kumar (Senior Executive - TPA, Billing) | F16: 8700319474 / 7428280579 | H16: insurance.mgroad@pbhealth.com
A17: BED COMPOSITION
A18: Type of Beds | B18: No. of Beds | C18: Rent Per Day | E18: Type of Beds | G18: No. of Beds | H18: Rent Per Day
A19: Total | B19: 100 | E19: Single Room with AC | G19: 35 | H19: 11000
A20: General Ward | B20: Nil | E20: Deluxe Rooms | G20: Nil
A21: Semi Private | B21: Nil | E21: Super Deluxe | G21: Nil
A22: Semi Private with AC | B22: 16 | C22: 7000 | E22: ICU | G22: 27 | H22: 12,000 (PICU 8,000)
A23: Single Room | B23: Nil | E23: Day Care | H23: 3750
A24: HOSPITAL INFRASTRUCTURE
A25: Medical Infrastructure | E25: Support Services
A26: Pathology Services | B26: Outsourced (Pathkind) | C26: Major OT | D26: 3 | E26: Parking Area available - Yes / No | I26: Yes
A27: X-Ray | B27: Yes | C27: Minor OT | E27: Biomedical Waste Management - Yes / No | I27: Yes
A28: CT Scan | B28: Yes | C28: Pharmacy | D28: Yes (IP) | E28: Central Sterile Supply Department (CSSD) -Yes / No | I28: Yes
A29: MRI | B29: Yes | C29: Burns Unit | D29: No | E29: Hospital Information Management System (HMIS) - Yes / No | I29: Yes
A30: Emergency Unit | B30: Yes | C30: Blood Bank | D30: No | E30: Home Health Care Services - Yes / No | I30: No
A31: LICENSES, ACCREDITATION AND CERTIFICATIONS
A32: Hospital Registration No. | B32: 0608601979 (Provisional) | D32: Expiry Date: | E32: 17-Dec-26 | F32: NABH Certification Level | H32: Not accredited
A33: Hospital Registered with | C33: District Registering Authority, Gurgaon (Clinical Establishments Act, 2010) | F33: Any other certification | H33: None
A34: FINANCIAL INFORMATION
A35: Account No.: | B35: 50200119112042 | D35: Beneficiary Name | E35: Medom Healthtech Private Limited | H35: Account Type | I35: Current
A36: Bank Name | B36: HDFC Bank | E36: Bank Address: | F36: First India Place, Mehrauli Gurgaon Road, Gurugram - 122002
A37: IFSC Code | B37: HDFC0000280 | C37: GST Number | D37: 06AATCM6271B1ZC | F37: PAN No. | G37: AATCM6271B | H37: Name on PAN Card | I37: Medom Healthtech Private Limited
A38: TDS Exemption % | B38: Not applicable | C38: TDS Exemption Limit | F38: TDS Exemption Period
A39: DISCOUNTS / BENEFITS OFFERED FOR SBI GENERAL DIRECT CASHLESS SERVICES
A40: OPD Services | B40: % Discount | C40: IPD Services | E40: % Discount | F40: Waiver offered on | I40: Yes / No
...

Sheet Sheet1
A1: Sr No | B1: HOSPITAL DATA SHEET | Y1: MAIN CONTACT POINTS | AK1: BED COMPOSITION | BO1: HOSPITAL INFRASTRUCTURE | CD1: LICENSES, ACCREDITATION AND CERTIFICATIONS | CI1: FINANCIAL INFORMATION | CU1: DISCOUNTS / BENEFITS OFFERED FOR SBI GENERAL DIRECT CASHLESS SERVICES
B2: HOSPITAL ROHINI ID* | C2: ROHINI Expiry Date | D2: Agreed Tariff | E2: Name of Hospital | F2: Address | G2: City | H2: State | I2: Pin Code | J2: STD Code | K2: Phone | L2: Fax | M2: E Mail ID | N2: Mobile No. | O2: Type of Provider | S2: Type of Provider / Ownership Type: | Y2: Head of the Organisation / CEO | AB2: MoU Signing Authority | AE2: Marketing | AH2: TPA Desk | BO2: Medical Infrastructure | BY2: Support Services
O3: Private | P3: Corporate | Q3: Charitable Trust | R3: Government | S3: Company | T3: Partnership Firm | U3: LLP | V3: Propritorship Concern | W3: Individual Person | X3: Trust | Y3: Name | Z3: Mobile No. | AA3: E Mail ID | AB3: Name | AC3: Mobile No. | AD3: E Mail ID | AE3: Name | AF3: Mobile No. | AG3: E Mail ID | AH3: Name | AI3: Mobile No. | AJ3: E Mail ID | AK3: Type of Beds | AL3: No. of Beds | AM3: Rent Per Day | AN3: Type of Beds | AO3: No. of Beds | AP3: Rent Per Day | AQ3: Type of Beds | AR3: No. of Beds | AS3: Rent Per Day | AT3: Type of Beds | AU3: No. of Beds | AV3: Rent Per Day | AW3: Type of Beds | AX3: No. of Beds | AY3: Rent Per Day | AZ3: Type of Beds | BA3: No. of Beds | BB3: Rent Per Day | BC3: Type of Beds | BD3: No. of Beds | BE3: Rent Per Day | BF3: Type of Beds | BG3: No. of Beds | BH3: Rent Per Day | BI3: Type of Beds | BJ3: No. of Beds | BK3: Rent Per Day | BL3: Type of Beds | BM3: No. of Beds | BN3: Rent Per Day | BO3: Pathology Services | BP3: X-Ray | BQ3: CT Scan | BR3: MRI | BS3: Emergency Unit | BT3: Major OT | BU3: Minor OT | BV3: Pharmacy | BW3: Burns Unit | BX3: Blood Bank | BY3: Parking Area available | BZ3: Biomedical Waste Management | CA3: Central Sterile Supply Department (CSSD) | CB3: Hospital Information Management System (HMIS) | CC3: Home Health Care Services | CD3: Hospital Registration No. | CE3: Expiry Date: | CF3: Hospital Registered with | CG3: NABH Certification Level | CH3: Any other certification | CI3: Account No.: | CJ3: Beneficiary Name | CK3: Bank Name | CL3: Bank Adress | CM3: Account Type | CN3: IFSC Code | CO3: PAN No. | CP3: Name on PAN Card | CQ3: GST Number | CR3: TDS Exemption % | CS3: TDS Exemption Limit | CT3: TDS Exemption Period | CU3: OPD Services | CV3: % Discount | CW3: OPD Services | CX3: % Discount | CY3: OPD Services | CZ3: % Discount | DA3: OPD Services | DB3: % Discount | DC3: IPD Services | DD3: % Discount | DE3: IPD Services | DF3: % Discount | DG3: IPD Services | DH3: % Discount | DI3: IPD Services | DJ3: % Discount | DK3: Waiver offered on | DL3: Yes / No | DM3: Waiver offered on | DN3: Yes / No | DO3: Waiver offered on | DP3: Yes / No | DQ3: Waiver offered on | DR3: Yes / No
A4: 1 | B4: =HIS!C2 -> 8900080770423 | C4: =HIS!I2 -> 17-Aug-2027 | D4: =HIS!I5 -> 0 | E4: =HIS!B3 -> PB Health Hospital, MG Road (Medom Healthtech Private Limited) | F4: =HIS!B4 -> L-22, DLF Phase 2, Mehrauli-Gurgaon Road, Sector 25, Near American Public School | G4: =HIS!B5 -> Gurugram | H4: =HIS!D5 -> Haryana | I4: =HIS!F5 -> Pincode: | J4: =HIS!B6 -> 0124 | K4: =HIS!E6 -> 4374109 | L4: =HIS!H6 -> Nil | M4: =HIS!B7 -> insurance.mgroad@pbhealth.com | N4: =HIS!G7 -> 7428280579 | O4: =HIS!C8 -> Yes | P4: =HIS!E8 -> 0 | Q4: =HIS!G8 -> 0 | R4: =HIS!I8 -> 0 | S4: =HIS!D9 -> Yes | T4: =HIS!G9 -> 0 | U4: =HIS!I9 -> 0 | V4: =HIS!D10 -> 0 | W4: =HIS!G10 -> 0 | X4: =HIS!I10 -> 0 | Y4: =HIS!C13 -> Alok Man Singh, Hospital Director | Z4: =HIS!F13 -> 0 | AA4: =HIS!H13 -> 0 | AB4: =HIS!C14 -> Manoj Sharma, Director / Rajeev Bhandari, Director | AC4: =HIS!F14 -> 9810302530 / 9873079038 | AD4: =HIS!H14 -> rajeev.bhandari@pbhealth.com | AE4: =HIS!C15 -> - | AF4: =HIS!F15 -> 0 | AG4: =HIS!H15 -> 0 | AH4: =HIS!C16 -> Deepak Kumar (Senior Executive - TPA, Billing) | AI4: =HIS!F16 -> 8700319474 / 7428280579 | AJ4: =HIS!H16 -> insurance.mgroad@pbhealth.com | AK4: Total | AL4: =HIS!B19 -> 100 | AM4: =HIS!C19 -> 0 | AN4: General Ward | AO4: =HIS!B20 -> Nil | AP4: =HIS!C20 -> 0 | AQ4: Semi Private | AR4: =HIS!B21 -> Nil | AS4: =HIS!C21 -> 0 | AT4: Semi Private with AC | AU4: =HIS!B22 -> 16 | AV4: =HIS!C22 -> 7000 | AW4: Single Room | AX4: =HIS!B23 -> Nil | AY4: =HIS!C23 -> 0 | AZ4: Single Room with AC | BA4: =HIS!G19 -> 35 | BB4: =HIS!H19 -> 11000 | BC4: Deluxe Rooms | BD4: =HIS!G20 -> Nil | BE4: =HIS!H20 -> 0 | BF4: Super Deluxe | BG4: =HIS!G21 -> Nil | BH4: =HIS!H21 -> 0 | BI4: ICU | BJ4: =HIS!G22 -> 27 | BK4: =HIS!H22 -> 12,000 (PICU 8,000) | BL4: Day Care | BM4: =HIS!G23 -> 0 | BN4: =HIS!H23 -> 3750 | BO4: =HIS!B26 -> Outsourced (Pathkind) | BP4: =HIS!B27 -> Yes | BQ4: =HIS!B28 -> Yes | BR4: =HIS!B29 -> Yes | BS4: =HIS!B30 -> Yes | BT4: =HIS!D26 -> 3 | BU4: =HIS!D27 -> 0 | BV4: =HIS!D28 -> Yes (IP) | BW4: =HIS!D29 -> No | BX4: =HIS!D30 -> No | BY4: =HIS!I26 -> Yes | BZ4: =HIS!I27 -> Yes | CA4: =HIS!I28 -> Yes | CB4: =HIS!I29 -> Yes | CC4: =HIS!I30 -> No | CD4: =HIS!C32 -> 0 | CE4: =HIS!E32 -> 17-Dec-26 | CF4: =HIS!C33 -> District Registering Authority, Gurgaon (Clinical Establishments Act, 2010) | CG4: =HIS!H32 -> Not accredited | CH4: =HIS!H33 -> None | CI4: =HIS!B35 -> 50200119112042 | CJ4: =HIS!E35 -> Medom Healthtech Private Limited | CK4: =HIS!B36 -> HDFC Bank | CL4: =HIS!F36 -> First India Place, Mehrauli Gurgaon Road, Gurugram - 122002 | CM4: =HIS!I35 -> Current | CN4: =HIS!B37 -> HDFC0000280 | CO4: =HIS!G37 -> AATCM6271B | CP4: =HIS!I37 -> Medom Healthtech Private Limited | CQ4: =HIS!D37 -> 06AATCM6271B1ZC | CR4: =HIS!B38 -> Not applicable | CS4: =HIS!E38 -> 0 | CT4: =HIS!H38 -> 0 | CU4: OPD Consultations | CV4: =HIS!B41 -> 0 | CW4: OPD Diagnostics | CX4: =HIS!B42 -> 0 | CY4: Health Check Ups | CZ4: =HIS!B43 -> 0 | DA4: Other OPD Services | DB4: =HIS!B44 -> 0 | DC4: Bed Charges | DD4: =HIS!E41 -> 0 | DE4: IPD Diagnostics | DF4: =HIS!E42 -> 0 | DG4: Other IPD Services | DH4: =HIS!E43 -> 0 | DI4: Total IPD Bill | DJ4: =HIS!E44 -> 0 | DK4: Registration / Admission Charges | DL4: =HIS!I41 -> 0 | DM4: Admission Deposit | DN4: =HIS!I42 -> 0 | DO4: Non-Medical Expenses up to INR 5000 | DP4: =HIS!I43 -> 0 | DQ4: Charges for expert health talks | DR4: =HIS!I44 -> 0
B7: TERMS AGREED WITH THE HOSPITAL
B8: Clause No. | C8: Item | E8: Agreed Term
B9: Clause 7.1 | C9: Payment Credit Period | E9: 60 days
B10: Clause 10.1 | C10: Agreement Commencement Date | E10: 1st April 2022
B11: Clause 15.1c | C11: In Case of Notice to the Network Provider | E11: Name: | F11: =HIS!B3 -> PB Health Hospital, MG Road (Medom Healthtech Private Limited)
E12: Address: | F12: =HIS!B4 -> L-22, DLF Phase 2, Mehrauli-Gurgaon Road, Sector 25, Near American Public School
E13: Phone: | F13: =HIS!B6&"-"&HIS!E6&"/"&HIS!G7 -> 0124-4374109/7428280579
E14: Facsimile: | F14: =HIS!H6 -> Nil
E15: E-mail: | F15: =HIS!B7 -> insurance.mgroad@pbhealth.com
C16: Agreement Signing Authority | E16: Name: | F16: =HIS!C13 -> Alok Man Singh, Hospital Director
E17: Designation: | F17: Head of the Organisation / CEO
B18: Annexure B | C18: Tariff applicable with respect to Services | E18: ATTACHED | F18: ATTACHED
B19: Annexure C | C19: Discount on total hospital bill (%) | E19: 10% discount on total hospital bill | F19: =HIS!E44 &"% discount on total hospital bill" -> % discount on total hospital bill
C20: Discount of _% on OPD Consultations & Investigations | E20: 0.1
C21: Discount of _% on Health Check-up Packages | E21: 10%
C22: Discount of _% on Items purchased from In House pharmacy | E22: 10%
C23: Natur of Entity | E23: Company / LLP/ Partership/
B24: Annexure N | C24: Tariff Locking and Credit Period | F24: 36 months / 60 Days
E25: Complimentary health camps / health awareness sessions at corporate sites | F25: Yes
E26: Health checkup camps / health awareness sessions on discounted price | F26: Yes
B27: Waiver offered on: - Yes / No | E27: Registration / Admission Charges | F27: =HIS!I41 -> 0
E28: Admission Deposit | F28: =HIS!I42 -> 0
E29: Non-Medical Expenses up to INR 5000 | F29: =HIS!I43 -> 0
E30: Charges for expert health talks | F30: =HIS!I44 -> 0
